Workbook

Sheet Methodology & Approach
A1: INDEPENDENT ASSESSMENT — METHODOLOGY & APPROACH
A2: SC-GL/6-2023 Guidelines on Technology Risk Management — Capital Market Intermediary
A4: ENGAGEMENT DETAILS
A5: Entity Name: | B5: [Entity Name]
A6: Regulated Activity: | B6: Capital Market Intermediary (CMSL/CMSRL Holder)
A7: Assessment Date: | B7: [DD/MM/YYYY]
A8: Assessment Period: | B8: [Start Date] to [End Date]
A9: Lead Assessor: | B9: [Name, Qualification]
A10: Engagement Reference: | B10: [Ref Number]
A11: Report Classification: | B11: Confidential (Sulit)
A13: SCOPE OF ASSESSMENT
A14: This assessment is conducted pursuant to SC-GL/6-2023 Guidelines on Technology Risk Management for capital market intermediaries regulated by the Securities Commission Malaysia.
A15: The objective is to ascertain that the entity has established and maintains an effective technology risk management framework covering governance, cybersecurity, resilience, third-party management, data protection, and emerging technology risks.
A16: Assessment covers 35 controls across 10 domains: (1) Governance & Oversight, (2) Technology Risk Assessment, (3) Cybersecurity, (4) Business Continuity, (5) Incident Management, (6) Third-Party Risk, (7) Cloud Services, (8) Data Management, (9) Technology Audit, (10) Emerging Technology.
A17: IMPORTANT: Third-party validation does not guarantee SC approval. Areas assessed reflect the assessor's professional judgement guided by SC-GL/6-2023 and may not cover every SC expectation.
A19: ASSESSMENT METHODS
A20: Inspection | B20: Examination of documents, records, policies, configurations, and tangible evidence to verify existence, completeness, and compliance with SC-GL/6-2023 requirements.
A21: Inquiry | B21: Interviews with management, process owners, and staff to understand controls and their operating effectiveness within the capital market entity.
A22: Observation | B22: Direct observation of processes, systems, and activities being performed.
A23: Confirmation | B23: Verification with external or independent parties (e.g., CSP certifications, third-party audit reports).
A25: SAMPLING METHODOLOGY
A26: This assessment uses judgemental (non-statistical) sampling. Sample sizes are determined by population size and control risk tier. The assessor exercises professional judgement in sample selection, prioritising items with higher inherent risk, recent changes, or anomalies identified during the assessment.
A28: Table 1 — Population-Based Sample Sizes
A29: Population Size | B29: Standard Risk | C29: High Risk (Critical Tier) | D29: Rationale
A30: 1–5 | B30: All | C30: All | D30: Full coverage feasible
A31: 6–15 | B31: 3 | C31: 5 | D31: ~25–40% coverage
A32: 16–50 | B32: 5 | C32: 8 | D32: Sufficient for pattern detection
A33: 51–100 | B33: 8 | C33: 12 | D33: Diminishing returns beyond this
A34: 100+ | B34: 10 | C34: 15 | D34: Cap with stratification
A36: Table 2 — Time-Based Evidence Coverage
A37: Evidence Type | B37: Coverage Period | C37: Rationale
A38: Board / committee reports | B38: Last 4 quarters | C38: Full annual governance cycle
A39: Operational records (incidents, changes, patches) | B39: Last 3–6 months | C39: Recent operating effectiveness
A40: Annual processes (risk assessment, DR test, pen test) | B40: Last 12 months | C40: Full cycle
A41: Continuous monitoring (SOC, logs, alerts) | B41: Last 30 days | C41: Current state verification
A42: Policies and frameworks | B42: Current version + prior | C42: Change tracking
A44: Table 3 — Control Risk Tier Classification
A45: Risk Tier | B45: Sampling Level | C45: Description | D45: Controls
A46: Critical | B46: High Risk column | C46: Foundation controls whose failure directly impacts market operations, regulatory standing, or client protection | D46: GRA-1, CYB-2, RIM-1, RIM-2, RIM-5, RIM-6, DET-3
A47: Standard | B47: Standard Risk column | C47: Controls that support effective technology risk management but whose absence has indirect or contained impact | D47: GRA-2–10, CYB-1/3/4, RIM-3/4/7/8, TPC-1–7, DET-1/2
...

Sheet Governance, Risk & Audit
A1: Ref | B1: Control | C1: Sub-Procedure | D1: Assessment Procedures | E1: Expected Evidence | F1: Method | G1: Procedures Performed | H1: Evidence Obtained | I1: Evidence Ref | J1: Observation / Findings | K1: Conclusion | L1: Recommendations | M1: Score
A2: GRA-1 — Technology Risk Governance Framework [CRITICAL]
A3: PURPOSE: SC-GL/6-2023 requires capital market intermediaries to establish a board-approved technology risk governance framework as the foundation for all technology risk management activities. This control ensures that governance structures, accountability, and oversight mechanisms are in place to protect market integrity, client assets, and operational resilience. EXPECTATION: The assessor should find a formally documented, board-approved governance framework with clearly defined roles and responsibilities, a functioning technology risk committee with cross-functional representation, and evidence of regular board-level engagement with technology risk matters. The framework should be current, reviewed within 12 months, and explicitly aligned with SC-GL/6-2023 requirements. KEY RISK: Without an effective governance framework, technology risk management operates without strategic direction or board accountability, increasing the likelihood of undetected control failures affecting trading operations, settlement integrity, and regulatory standing with the Securities Commission.
A4: GRA-1 | B4: Technology Risk Governance Framework | C4: Governance structure & reporting lines | D4: 1. Obtain the board-approved technology risk governance framework document. 2. Verify it defines governance structure with clear roles, responsibilities, and reporting lines from board level through operational management. 3. Confirm a technology risk committee (or equivalent) exists with cross-functional representation. 4. Review committee meeting minutes (last 4 quarters) for attendance, quorum, and decision-making evidence. | E4: Board-approved governance framework; Technology risk committee charter; Committee meeting minutes (last 4 quarters); Organisational chart showing reporting lines; Committee attendance records | F4: Inspection / Inquiry | M4: =IF(K4="Compliant",3,IF(K4="Partially Compliant",2,IF(K4="Non-Compliant",1,"")))
A5: GRA-1 | B5: Technology Risk Governance Framework | C5: Board approval & annual review cycle | D5: 1. Inspect the governance framework document for board approval evidence (board resolution, signed approval page, or minutes recording approval). 2. Verify the framework version history and confirm the last review date is within 12 months. 3. Determine whether out-of-cycle reviews are triggered by material changes such as new SC guidance, significant incidents, or organisational restructuring. 4. Review board agenda and papers for the most recent annual review to verify the board received adequate information to assess the framework's adequacy. | E5: Board resolution or approval record; Framework version history log; Board meeting agenda and papers for last annual framework review; Out-of-cycle review trigger criteria (if documented) | F5: Inspection | M5: =IF(K5="Compliant",3,IF(K5="Partially Compliant",2,IF(K5="Non-Compliant",1,"")))
A6: GRA-1 | B6: Technology Risk Governance Framework | C6: Three lines of defence model | D6: 1. Interview the CISO or committee chair to understand how the three lines of defence model is implemented for technology risk management. 2. Verify that first line (technology operations and business units), second line (risk management and compliance), and third line (internal audit) roles are clearly delineated and documented. 3. Confirm independence between the lines — specifically that second-line risk oversight is not conflated with first-line technology delivery. 4. Review a sample of 3 risk decisions (per sampling methodology) to trace how the three lines interacted (e.g., risk acceptance, control exception). | E6: Three lines of defence model documentation; RACI matrix for technology risk responsibilities; Sample risk decision records (3) showing line interactions; Organisational chart demonstrating independence between lines | F6: Inspection / Inquiry | M6: =IF(K6="Compliant",3,IF(K6="Partially Compliant",2,IF(K6="Non-Compliant",1,"")))
A7: GRA-1 | B7: Technology Risk Governance Framework | C7: Technology risk appetite statement | D7: 1. Obtain the documented technology risk appetite statement and verify it is aligned with the entity's overall business strategy and risk appetite. 2. Confirm the risk appetite statement addresses capital market-specific risk dimensions (e.g., trading system availability, settlement failure tolerance, market data integrity). 3. Verify the risk appetite has been approved by the board and is reviewed at least annually. 4. Assess whether the risk appetite is operationalised through defined risk tolerance levels and Key Risk Indicators with escalation thresholds. | E7: Board-approved technology risk appetite statement; Risk tolerance levels and KRI threshold definitions; Board approval evidence for risk appetite; Mapping of risk appetite to capital market operational risk dimensions | F7: Inspection | M7: =IF(K7="Compliant",3,IF(K7="Partially Compliant",2,IF(K7="Non-Compliant",1,"")))
A8: GRA-1 | B8: Technology Risk Governance Framework | C8: Committee effectiveness & decision quality | D8: 1. Review technology risk committee meeting minutes from the last 4 quarters for evidence of substantive discussion, challenge, and decision-making. 2. Verify that the committee receives and acts on key inputs: risk reports, incident summaries, audit findings, and emerging risk briefings. 3. Confirm that committee action items are tracked to closure by reviewing the action register. 4. Assess committee membership for appropriate seniority and cross-functional representation including trading, operations, compliance, and technology. | E8: Committee meeting minutes (last 4 quarters); Committee action item register with closure tracking; Committee membership list with roles and seniority; Agenda and supporting papers for last 2 meetings | F8: Inspection | M8: =IF(K8="Compliant",3,IF(K8="Partially Compliant",2,IF(K8="Non-Compliant",1,"")))
A9: GRA-1 | B9: Technology Risk Governance Framework | C9: Alignment with SC-GL/6-2023 requirements | D9: 1. Map the governance framework's coverage against SC-GL/6-2023 guideline requirements for governance and oversight. 2. Identify any gaps where SC expectations are not explicitly addressed in the governance framework. 3. Verify that the framework references SC-GL/6-2023 as the primary regulatory driver and is updated when SC issues new guidance or advisories. 4. Confirm that governance arrangements address SC-specific expectations for capital market intermediaries, including oversight of trading systems, client data protection, and market integrity. | E9: SC-GL/6-2023 coverage mapping or gap analysis; Framework sections referencing SC guidelines; Records of framework updates following SC guidance changes; SC advisory review log | F9: Inspection | M9: =IF(K9="Compliant",3,IF(K9="Partially Compliant",2,IF(K9="Non-Compliant",1,"")))
A10: GRA-2 — CISO Designation & Authority
A11: PURPOSE: SC-GL/6-2023 requires capital market intermediaries to designate a CISO with adequate authority, independence, and resources to oversee cybersecurity and technology risk. This ensures a single accountable executive drives the security programme and has unimpeded access to the board. EXPECTATION: The assessor should find a formally appointed CISO with relevant qualifications and certifications, reporting independently from technology delivery, with demonstrated board access and a standing reporting slot. The CISO should have an adequately resourced team and documented authority to influence technology decisions. KEY RISK: Without a designated, independent CISO, security priorities are subordinated to delivery timelines, creating blind spots in risk oversight that can lead to undetected vulnerabilities in trading systems and delayed incident response.
A12: GRA-2 | B12: CISO Designation & Authority | C12: CISO appointment & qualifications | D12: 1. Obtain the CISO's appointment letter, board resolution, or designation record confirming the formal appointment. 2. Review the CISO's qualifications, professional certifications (e.g., CISSP, CISM), and experience relevant to technology risk and capital market operations. 3. Verify the CISO is appointed on a full-time, dedicated basis and that the role is not combined with technology delivery responsibilities. 4. Confirm the appointment is documented in a job description that defines the scope of authority over all technology and cybersecurity risk domains. | E12: CISO appointment letter or board resolution; CISO curriculum vitae with qualifications and certifications; Job description defining scope and authority; Organisation announcement or HR confirmation of dedicated full-time role | F12: Inspection | M12: =IF(K12="Compliant",3,IF(K12="Partially Compliant",2,IF(K12="Non-Compliant",1,"")))
A13: GRA-2 | B13: CISO Designation & Authority | C13: Reporting independence | D13: 1. Review the organisational chart to confirm the CISO's reporting line is independent from the CTO or Head of IT Operations. 2. Verify the CISO has direct access to senior management and/or board committee without requiring CTO or IT head approval. 3. Interview the CISO to assess the practical reality of independence — specifically whether security recommendations are overridden by technology delivery priorities without appropriate escalation. 4. Confirm escalation procedures exist that allow the CISO to raise unresolved concerns directly to the board if necessary. | E13: Organisational chart showing CISO reporting line; Escalation procedure documentation; CISO interview notes confirming practical independence; Evidence of CISO-board direct communication channel | F13: Inspection / Inquiry | M13: =IF(K13="Compliant",3,IF(K13="Partially Compliant",2,IF(K13="Non-Compliant",1,"")))
A14: GRA-2 | B14: CISO Designation & Authority | C14: Board reporting & engagement | D14: 1. Review board or board committee minutes from the last 4 quarters to verify the CISO presented or reported to the board on technology and cybersecurity risk. 2. Confirm the board meeting records document substantive discussion, questions raised, and actions taken in response to CISO reporting. 3. Verify the CISO has a standing agenda slot at the board risk committee or equivalent. 4. Assess the quality and comprehensiveness of CISO board reports — they should cover risk posture, incidents, compliance, emerging threats, and strategic security initiatives. | E14: Board/committee minutes documenting CISO presentations (last 4 quarters); CISO board reports or presentation materials; Board risk committee agenda showing CISO standing item; Records of board actions or directives arising from CISO reporting | F14: Inspection | M14: =IF(K14="Compliant",3,IF(K14="Partially Compliant",2,IF(K14="Non-Compliant",1,"")))
A15: GRA-2 | B15: CISO Designation & Authority | C15: Resources & budget adequacy | D15: 1. Obtain the security team structure and headcount under the CISO's authority. 2. Review the approved security budget for the current financial year and compare against industry benchmarks for capital market intermediaries. 3. Interview the CISO to assess whether resource constraints limit the ability to discharge responsibilities effectively. 4. Verify that the CISO has authority to approve security expenditure within the approved budget without requiring CTO sign-off. | E15: Security team organisational chart and headcount; Approved security budget for current year; CISO budget authority documentation; CISO interview notes on resource adequacy | F15: Inspection / Inquiry | M15: =IF(K15="Compliant",3,IF(K15="Partially Compliant",2,IF(K15="Non-Compliant",1,"")))
A16: GRA-2 | B16: CISO Designation & Authority | C16: CISO authority in practice | D16: 1. Review 3 instances (per sampling methodology) where the CISO exercised authority to influence technology decisions (e.g., halting a deployment, requiring security controls, rejecting a vendor). 2. Determine whether the CISO has the authority to halt a technology deployment if security risks are deemed unacceptable. 3. Verify that the CISO's role and authority are communicated to all relevant stakeholders including technology, trading, and business unit heads. 4. Assess whether the CISO participates in strategic technology decisions such as new system selection, cloud adoption, and algorithmic trading platform changes. | E16: Records of CISO-influenced technology decisions (3 instances); CISO authority policy or terms of reference; Evidence of CISO participation in strategic technology decision forums; Communication records notifying stakeholders of CISO authority | F16: Inspection / Inquiry | M16: =IF(K16="Compliant",3,IF(K16="Partially Compliant",2,IF(K16="Non-Compliant",1,"")))
A17: GRA-3 — Technology Risk Policy Suite
A18: PURPOSE: SC-GL/6-2023 requires capital market intermediaries to maintain a comprehensive suite of technology risk policies covering all guideline domains. This ensures that governance expectations are translated into enforceable standards that guide day-to-day operations across cybersecurity, data management, access control, and change management. EXPECTATION: The assessor should find a complete, board-approved policy suite that maps to all SC-GL/6-2023 domains, with each policy reviewed within 12 months, communicated to relevant personnel, and containing capital market-specific provisions. Policies should be enforceable with measurable standards rather than aspirational statements. KEY RISK: An incomplete or outdated policy suite creates ambiguity in expected controls, leaves staff without clear guidance on capital market-specific requirements, and exposes the intermediary to regulatory findings for non-compliance with SC-GL/6-2023 documentation expectations.
A19: GRA-3 | B19: Technology Risk Policy Suite | C19: Policy inventory & SC-GL/6-2023 coverage | D19: 1. Obtain the complete technology risk policy inventory listing all current policies. 2. Map the policy inventory against SC-GL/6-2023 domain requirements to verify coverage of: cybersecurity, technology risk assessment, data management, cloud services, third-party risk, incident management, business continuity, and technology audit. 3. Identify any domains where no corresponding policy exists and assess the entity's plan to address gaps. 4. Verify that each policy explicitly references the SC-GL/6-2023 requirements it addresses. | E19: Technology risk policy inventory or register; SC-GL/6-2023 domain coverage mapping; Gap analysis (if gaps identified); Sample policies showing SC-GL/6-2023 references | F19: Inspection | M19: =IF(K19="Compliant",3,IF(K19="Partially Compliant",2,IF(K19="Non-Compliant",1,"")))
A20: GRA-3 | B20: Technology Risk Policy Suite | C20: Board approval & review cycle | D20: 1. For each policy in the suite, verify board approval evidence (signature, board resolution, or minutes recording approval). 2. Confirm the last review date for each policy is within 12 months. 3. Review the policy review schedule and verify it is maintained and adhered to. 4. Determine whether policies have been updated to reflect recent SC advisories, regulatory changes, or significant incidents in the last 12 months. | E20: Board approval records for each policy (signatures, resolutions, or minutes); Policy review schedule; Policy version history showing last review dates; Records of policy updates following regulatory changes | F20: Inspection | M20: =IF(K20="Compliant",3,IF(K20="Partially Compliant",2,IF(K20="Non-Compliant",1,"")))
A21: GRA-3 | B21: Technology Risk Policy Suite | C21: Cybersecurity policy | D21: 1. Obtain the cybersecurity policy and verify it covers: threat management, security monitoring, vulnerability management, network security, endpoint protection, and security awareness. 2. Confirm the policy addresses capital market-specific cybersecurity requirements including protection of trading systems, market data integrity, and client portal security. 3. Verify the policy defines roles and responsibilities for cybersecurity across the three lines of defence. 4. Assess whether the policy establishes measurable security standards (e.g., patching SLAs, monitoring coverage targets, incident response timelines). | E21: Board-approved cybersecurity policy; Policy sections addressing capital market-specific requirements; Cybersecurity RACI matrix; Defined security standards and SLAs within the policy | F21: Inspection | M21: =IF(K21="Compliant",3,IF(K21="Partially Compliant",2,IF(K21="Non-Compliant",1,"")))
A22: GRA-3 | B22: Technology Risk Policy Suite | C22: Access control policy | D22: 1. Obtain the access control policy and verify it covers: user provisioning and de-provisioning, role-based access, privileged access management, multi-factor authentication, and periodic access reviews. 2. Confirm the policy mandates least-privilege access for all capital market systems including trading platforms, settlement systems, and client data repositories. 3. Verify that the policy addresses access control requirements for remote access, vendor access, and emergency access scenarios. 4. Review whether the policy defines access review frequency (at least quarterly for privileged access, at least annually for standard access). | E22: Board-approved access control policy; Policy sections on privileged access and MFA requirements; Access review frequency requirements; Remote and vendor access control provisions | F22: Inspection | M22: =IF(K22="Compliant",3,IF(K22="Partially Compliant",2,IF(K22="Non-Compliant",1,"")))
A23: GRA-3 | B23: Technology Risk Policy Suite | C23: Data security & privacy policy | D23: 1. Obtain the data security and privacy policy and verify it covers: data classification, encryption standards, data loss prevention, data retention, and disposal. 2. Confirm the policy addresses PDPA compliance requirements for client personal data held by the capital market intermediary. 3. Verify the policy defines data handling requirements specific to market data, client trading information, and corporate confidential data. 4. Assess whether the policy establishes encryption standards (AES-256 at rest, TLS 1.2+ in transit) and data residency requirements consistent with SC and PDPA expectations. | E23: Board-approved data security and privacy policy; PDPA compliance provisions within the policy; Data classification scheme referenced by the policy; Encryption and data residency standards defined in the policy | F23: Inspection | M23: =IF(K23="Compliant",3,IF(K23="Partially Compliant",2,IF(K23="Non-Compliant",1,"")))
A24: GRA-3 | B24: Technology Risk Policy Suite | C24: Change management policy | D24: 1. Obtain the change management policy and verify it defines: change classification (critical, significant, standard), risk assessment requirements, testing and approval gates, and rollback procedures. 2. Confirm the policy addresses change freeze periods around critical market events (e.g., settlement cycles, quarter-end, market launches). 3. Verify the policy establishes special controls for changes to trading systems, settlement systems, and market connectivity. 4. Assess whether the policy defines emergency change procedures with retrospective risk assessment and approval requirements. | E24: Board-approved change management policy; Change classification criteria; Change freeze period definitions; Emergency change procedures; Special controls for trading system changes | F24: Inspection | M24: =IF(K24="Compliant",3,IF(K24="Partially Compliant",2,IF(K24="Non-Compliant",1,"")))
A25: GRA-3 | B25: Technology Risk Policy Suite | C25: Additional policy areas (BCP, cloud, outsourcing, incident management) | D25: 1. Verify that policies exist for: business continuity and disaster recovery, cloud services governance, technology outsourcing, and incident management and response. 2. For each, confirm board approval and review within the last 12 months. 3. Assess whether each policy is aligned with the corresponding SC-GL/6-2023 domain requirements and references the guideline. 4. Review a sample of 3 additional policies (per sampling methodology) in detail for adequacy of content, clarity of responsibilities, and enforceability. | E25: BCP/DR policy (board-approved); Cloud services policy (board-approved); Technology outsourcing policy (board-approved); Incident management policy (board-approved); Board approval and review date evidence for each | F25: Inspection | M25: =IF(K25="Compliant",3,IF(K25="Partially Compliant",2,IF(K25="Non-Compliant",1,"")))
A26: GRA-3 | B26: Technology Risk Policy Suite | C26: Policy communication & awareness | D26: 1. Inspect evidence of policy communication to all relevant personnel (e.g., intranet publication, email distribution, training records, acknowledgement logs). 2. Review policy acknowledgement records to verify staff have confirmed receipt and understanding. 3. Interview 3 staff from different functions (per sampling methodology) (e.g., trading, operations, IT) to verify awareness and ability to locate key technology risk policies. 4. Verify that policy communication extends to relevant third-party service providers where contractually required. | E26: Policy distribution records or intranet publication evidence; Staff acknowledgement logs; Training completion records for policy awareness; Third-party policy communication records; Interview notes from 3 staff across functions | F26: Inspection / Inquiry | M26: =IF(K26="Compliant",3,IF(K26="Partially Compliant",2,IF(K26="Non-Compliant",1,"")))
A27: GRA-4 — Technology Risk Reporting
A28: PURPOSE: SC-GL/6-2023 requires capital market intermediaries to provide regular, comprehensive technology risk reporting to the board and senior management. This ensures informed decision-making on technology risks that could impact market operations, client protection, and regulatory compliance. EXPECTATION: The assessor should find a consistent quarterly reporting cadence with reports covering all SC-GL/6-2023 domains, defined KRIs with escalation thresholds, emerging risk commentary, and audit remediation tracking. Board minutes should evidence substantive engagement with the reports, not just receipt. KEY RISK: Inadequate risk reporting leaves the board unable to exercise effective oversight, meaning material technology risks affecting trading systems, client data, or market integrity may persist without senior management awareness or intervention.
A29: GRA-4 | B29: Technology Risk Reporting | C29: Reporting cadence & completeness | D29: 1. Obtain technology risk reports submitted to the board or board committee for the last 4 quarters. 2. Verify a consistent quarterly (or more frequent) reporting cadence with no gaps. 3. Review report content for inclusion of: key risk indicators, incident trends, compliance metrics, audit remediation status, and emerging technology risk commentary. 4. Confirm reports cover all SC-GL/6-2023 domains and are not limited to cybersecurity incidents alone. | E29: Technology risk reports (last 4 quarters); Board committee agenda confirming standing reporting item; Report content checklist or template; Reports covering all GTRM domains | F29: Inspection | M29: =IF(K29="Compliant",3,IF(K29="Partially Compliant",2,IF(K29="Non-Compliant",1,"")))
A30: GRA-4 | B30: Technology Risk Reporting | C30: Key Risk Indicators & thresholds | D30: 1. Obtain the documented KRI definitions and thresholds for technology risk. 2. Verify that KRIs cover capital market-specific risk dimensions: trading system availability, settlement failure rates, cybersecurity incident counts, patch compliance, and vendor SLA performance. 3. Confirm escalation triggers are defined for threshold breaches and review evidence that breaches have been escalated in practice. 4. Assess whether KRI thresholds are calibrated periodically (at least annually) and reviewed for continued appropriateness. | E30: KRI definitions and threshold document; Evidence of threshold breach escalation (last 12 months); KRI calibration review records; Capital market-specific KRI examples (system availability, settlement failure rate) | F30: Inspection | M30: =IF(K30="Compliant",3,IF(K30="Partially Compliant",2,IF(K30="Non-Compliant",1,"")))
A31: GRA-4 | B31: Technology Risk Reporting | C31: Board engagement with risk reports | D31: 1. Review board or board committee minutes from the last 4 quarters to confirm discussion of technology risk reports. 2. Verify that minutes record board questions, challenges, and decisions taken in response to risk reporting. 3. Confirm that board directives or action items arising from risk reporting are tracked to completion. 4. Assess whether the board has requested deeper analysis or additional reporting on specific risk areas in the last 12 months. | E31: Board/committee minutes documenting risk report discussion (last 4 quarters); Board action items arising from risk reports; Evidence of board-requested deep-dive analyses; Board directive tracking log | F31: Inspection | M31: =IF(K31="Compliant",3,IF(K31="Partially Compliant",2,IF(K31="Non-Compliant",1,"")))
A32: GRA-4 | B32: Technology Risk Reporting | C32: Emerging risk identification & reporting | D32: 1. Review the last 4 quarterly reports for inclusion of emerging technology risk commentary. 2. Verify that emerging risks reported are relevant to capital market operations (e.g., AI/ML risks in algorithmic trading, quantum computing threats, supply chain attacks, new SC regulatory requirements). 3. Confirm the entity has a process for identifying emerging risks through horizon scanning, industry intelligence, and SC advisory monitoring. 4. Interview the CISO or CRO to understand how emerging risks are identified, assessed, and prioritised for board reporting. | E32: Emerging risk sections from quarterly reports; Horizon scanning or emerging risk identification process documentation; SC advisory monitoring log; CISO/CRO interview notes on emerging risk process | F32: Inspection / Inquiry | M32: =IF(K32="Compliant",3,IF(K32="Partially Compliant",2,IF(K32="Non-Compliant",1,"")))
A33: GRA-4 | B33: Technology Risk Reporting | C33: Audit finding remediation reporting | D33: 1. Verify that technology risk reports include the status of audit finding remediation. 2. Review the remediation tracking section of the most recent 2 quarterly reports for accuracy — cross-check against the audit findings tracker. 3. Confirm that overdue findings are highlighted and escalated to the board with owner accountability. 4. Assess whether the board has visibility over the ageing profile of open audit findings and trend over time. | E33: Audit remediation status sections from quarterly reports (last 2 quarters); Audit findings tracker for cross-reference; Board escalation records for overdue findings; Ageing profile of open findings | F33: Inspection | M33: =IF(K33="Compliant",3,IF(K33="Partially Compliant",2,IF(K33="Non-Compliant",1,"")))
A34: GRA-5 — Technology Risk Assessment Framework
A35: PURPOSE: SC-GL/6-2023 requires capital market intermediaries to maintain a structured technology risk assessment framework that identifies, assesses, and treats technology risks across all capital market operations. This ensures risks are systematically managed rather than addressed ad hoc. EXPECTATION: The assessor should find a documented risk assessment methodology with capital market-specific risk categories, a current risk register with assigned owners and treatment plans, annual comprehensive assessments completed within 12 months, and integration with the enterprise risk management framework. Out-of-cycle assessment triggers should be defined for material changes. KEY RISK: Without a structured risk assessment framework, technology risks affecting trading systems, settlement infrastructure, and market data integrity may be unidentified or underestimated, leading to inadequate controls and potential market disruption.
A36: GRA-5 | B36: Technology Risk Assessment Framework | C36: Risk assessment methodology | D36: 1. Obtain the technology risk assessment methodology document. 2. Verify it defines risk identification approaches, likelihood and impact assessment criteria, risk rating scales, and treatment options aligned with SC-GL/6-2023. 3. Confirm the methodology addresses capital market-specific risk categories including trading system failure, settlement disruption, market data corruption, and client data breach. 4. Assess whether the methodology is consistent with the entity's enterprise risk management framework. | E36: Technology risk assessment methodology document; Risk rating scales and criteria; Capital market-specific risk category definitions; ERM framework alignment mapping | F36: Inspection | M36: =IF(K36="Compliant",3,IF(K36="Partially Compliant",2,IF(K36="Non-Compliant",1,"")))
A37: GRA-5 | B37: Technology Risk Assessment Framework | C37: Annual comprehensive risk assessment | D37: 1. Obtain the most recent annual technology risk assessment report. 2. Verify the assessment covers all capital market technology domains: trading systems, settlement and clearing infrastructure, market data systems, client portals, and supporting IT infrastructure. 3. Confirm the assessment identifies specific risks, assigns risk ratings, and documents treatment decisions with assigned owners. 4. Verify the assessment was completed within the last 12 months and results were presented to senior management and the board. | E37: Annual technology risk assessment report (last 12 months); Risk register extract showing identified risks, ratings, and owners; Board or senior management presentation of assessment results; Assessment scope documentation covering all capital market domains | F37: Inspection | M37: =IF(K37="Compliant",3,IF(K37="Partially Compliant",2,IF(K37="Non-Compliant",1,"")))
A38: GRA-5 | B38: Technology Risk Assessment Framework | C38: Risk treatment & tracking | D38: 1. Select a sample of 5 high-rated technology risks from the risk register (per sampling methodology). 2. For each, trace through to the treatment plan and verify it documents: treatment approach (mitigate, accept, transfer, avoid), specific actions, responsible owner, target date, and current status. 3. Confirm that risk acceptances are approved at the appropriate level of authority and documented with compensating controls where applicable. 4. Verify that the risk register is maintained as a living document with regular updates — not only updated at annual assessment time. | E38: Risk register with treatment plans (sample of 5 high-rated risks per sampling methodology); Risk acceptance approvals with authority evidence; Treatment action tracking log; Risk register update history showing regular maintenance | F38: Inspection | M38: =IF(K38="Compliant",3,IF(K38="Partially Compliant",2,IF(K38="Non-Compliant",1,"")))
A39: GRA-5 | B39: Technology Risk Assessment Framework | C39: ERM integration | D39: 1. Interview the CRO or risk management team to understand how technology risk assessment results feed into the enterprise risk register and risk appetite monitoring. 2. Verify that technology risks are represented in the enterprise risk register at an appropriate level of granularity. 3. Confirm that technology risk assessments use consistent scales and terminology with the enterprise risk framework to enable comparison. 4. Assess whether technology risk reporting to the board is integrated with enterprise risk reporting or delivered as a separate, disconnected stream. | E39: Enterprise risk register showing technology risk entries; ERM framework referencing technology risk integration; CRO/risk team interview notes; Board risk report showing integrated technology and enterprise risk view | F39: Inspection / Inquiry | M39: =IF(K39="Compliant",3,IF(K39="Partially Compliant",2,IF(K39="Non-Compliant",1,"")))
A40: GRA-5 | B40: Technology Risk Assessment Framework | C40: Out-of-cycle risk assessment triggers | D40: 1. Verify that documented triggers exist for conducting out-of-cycle technology risk assessments (e.g., major system changes, significant incidents, new SC guidance, material market events). 2. Review whether any out-of-cycle assessments have been conducted in the last 12 months and assess their adequacy. 3. Confirm that the trigger criteria are aligned with capital market operating conditions, including triggers related to Bursa Malaysia system changes, new trading products, and regulatory changes. 4. Interview the risk team to understand how ad-hoc risk assessments are initiated and whether the process is responsive enough for fast-moving market conditions. | E40: Out-of-cycle assessment trigger criteria documentation; Records of out-of-cycle assessments conducted (last 12 months, if any); Risk team interview notes on trigger responsiveness; Trigger criteria referencing capital market events | F40: Inspection / Inquiry | M40: =IF(K40="Compliant",3,IF(K40="Partially Compliant",2,IF(K40="Non-Compliant",1,"")))
...

Sheet Cybersecurity
A1: Ref | B1: Control | C1: Sub-Procedure | D1: Assessment Procedures | E1: Expected Evidence | F1: Method | G1: Procedures Performed | H1: Evidence Obtained | I1: Evidence Ref | J1: Observation / Findings | K1: Conclusion | L1: Recommendations | M1: Score
A2: CYB-1 — Cyber Threat Management
A3: PURPOSE: SC-GL/6-2023 requires capital market intermediaries to maintain a proactive cyber threat management capability that identifies, assesses, and responds to threats targeting capital market operations. This ensures the entity operates with current threat awareness rather than relying solely on reactive defences. EXPECTATION: The assessor should find an active threat intelligence programme with feeds relevant to the capital market sector (including MyCERT and SC advisories), periodic threat assessments covering capital market-specific scenarios, documented threat hunting activity, participation in industry information-sharing initiatives, and regular threat landscape reporting to the board with actionable recommendations. KEY RISK: Without effective cyber threat management, the intermediary operates blind to evolving threats targeting trading systems, market data infrastructure, and client assets, increasing the likelihood of a successful attack that disrupts market operations or compromises client data.
A4: CYB-1 | B4: Cyber Threat Management | C4: Threat intelligence programme | D4: 1. Obtain documentation of the threat intelligence programme, including subscribed feeds (government, commercial, industry) and verify each feed is active with current subscriptions. 2. Verify that subscribed feeds include sources relevant to capital market threats (e.g., MyCERT, SC Malaysia advisories, FS-ISAC, commercial CTI providers covering APAC financial sector). 3. Review the feed ingestion process and confirm threat intelligence is parsed, triaged, and routed to SOC analysts within defined SLAs. 4. Inspect a sample of 5 threat intelligence items (per sampling methodology) received in the last 6 months and trace each from ingestion through assessment to action taken (e.g., IOC deployment, detection rule creation, patch prioritisation). | E4: Threat intelligence programme charter or procedure document; list of subscribed CTI feeds with subscription confirmations; sample threat intelligence triage records (5 items, last 6 months per sampling methodology); IOC deployment logs | F4: Inspection / Inquiry | M4: =IF(K4="Compliant",3,IF(K4="Partially Compliant",2,IF(K4="Non-Compliant",1,"")))
A5: CYB-1 | B5: Cyber Threat Management | C5: Capital market threat assessment | D5: 1. Obtain the last 2 periodic threat assessment reports (covering the last 12 months per sampling methodology) and verify they address capital market-specific threat scenarios. 2. Confirm assessments cover relevant threat categories: trading system attacks, market data manipulation, DDoS against exchange connectivity, ransomware targeting settlement infrastructure, insider trading facilitation, and state-sponsored threats to financial markets. 3. Verify threat assessments reference the entity's specific technology footprint (trading platforms, OMS/EMS, market data feeds, Bursa Malaysia connectivity). 4. Review how threat assessment findings have been translated into updated risk ratings or control priorities in the technology risk register. | E5: Periodic threat assessment reports (last 2 cycles); technology risk register with threat-driven updates; threat scenario documentation referencing capital market systems | F5: Inspection | M5: =IF(K5="Compliant",3,IF(K5="Partially Compliant",2,IF(K5="Non-Compliant",1,"")))
A6: CYB-1 | B6: Cyber Threat Management | C6: Threat hunting capability | D6: 1. Interview threat hunting personnel (or SOC analysts performing hunting duties) to understand hunting methodology, tools, and frequency. 2. Obtain threat hunting reports or logs from the last 12 months (per sampling methodology) and verify at least 3 proactive hunts were conducted (per sampling methodology). 3. Review hunting hypotheses to confirm they target advanced persistent threats relevant to capital market intermediaries (e.g., credential theft targeting trading systems, lateral movement toward settlement infrastructure, data exfiltration of client positions). 4. Determine whether hunting findings have resulted in new detection rules, IOC updates, or control improvements. 5. Verify that threat hunting covers algorithmic trading infrastructure and market data feed systems, not just generic enterprise IT. | E6: Threat hunting reports (last 12 months per sampling methodology); hunting hypothesis documentation; new detection rules created from hunting findings; threat hunting tools inventory | F6: Inspection / Inquiry | M6: =IF(K6="Compliant",3,IF(K6="Partially Compliant",2,IF(K6="Non-Compliant",1,"")))
A7: CYB-1 | B7: Cyber Threat Management | C7: Threat information sharing | D7: 1. Obtain evidence of participation in SC Malaysia threat information sharing initiatives, MyCERT coordination, and any capital market industry working groups or ISACs. 2. Review records of threat intelligence shared with and received from peer institutions, regulators, and industry bodies over the last 12 months. 3. Verify the entity has designated contacts and defined procedures for receiving and acting on SC advisories and MyCERT alerts. 4. Confirm participation records show active engagement (not merely membership) through meeting attendance, intelligence contributions, or exercise participation. | E7: SC advisory distribution and acknowledgement records; MyCERT coordination records; ISAC or working group membership and attendance records (last 12 months); evidence of intelligence contributions shared externally | F7: Inspection / Inquiry | M7: =IF(K7="Compliant",3,IF(K7="Partially Compliant",2,IF(K7="Non-Compliant",1,"")))
A8: CYB-1 | B8: Cyber Threat Management | C8: Threat landscape reporting | D8: 1. Obtain threat landscape reports or briefings provided to senior management and the board over the last 4 quarters. 2. Verify reports cover emerging threats to the capital market sector, threat actor trends (nation-state, organised crime, hacktivists), and specific risks to the entity's market operations. 3. Confirm reports include actionable recommendations and track implementation status of previously recommended actions. 4. Review whether threat landscape reporting has triggered any out-of-cycle risk assessments, budget requests, or control enhancements. | E8: Quarterly threat landscape reports or board briefing slides (last 4 quarters); board/committee meeting minutes noting threat briefing discussions; action item tracking from threat briefings | F8: Inspection | M8: =IF(K8="Compliant",3,IF(K8="Partially Compliant",2,IF(K8="Non-Compliant",1,"")))
A9: CYB-1 | B9: Cyber Threat Management | C9: Threat-driven control updates | D9: 1. Select a sample of 3 significant threat intelligence items or threat assessment findings from the last 12 months (per sampling methodology) and trace each to corresponding control updates. 2. Verify the process from threat identification to control update follows a defined workflow with documented approvals and timelines. 3. Review examples of control updates driven by threat intelligence (e.g., new firewall rules, updated detection signatures, additional access restrictions on trading systems, patching prioritisation changes). 4. Confirm that a feedback loop exists where control effectiveness is re-assessed after threat-driven changes are implemented. | E9: Change records linked to threat intelligence triggers; detection rule update logs; firewall change requests referencing threat intelligence; post-implementation verification records | F9: Inspection | M9: =IF(K9="Compliant",3,IF(K9="Partially Compliant",2,IF(K9="Non-Compliant",1,"")))
A10: CYB-2 — Security Operations Centre [CRITICAL]
A11: PURPOSE: SC-GL/6-2023 requires capital market intermediaries to maintain a security operations centre (SOC) as the primary detection and monitoring capability for cyber threats to capital market systems. The SOC is the frontline defence that detects attacks on trading platforms, settlement systems, and market data infrastructure in real time. EXPECTATION: The assessor should find a SOC with appropriate architecture and staffing for 24/7 coverage, comprehensive SIEM log source coverage including all critical capital market systems, detection rules tuned for capital market-specific attack patterns, enhanced monitoring during Bursa Malaysia trading hours, documented alert handling with defined SLAs, regular performance metrics reporting, and periodic effectiveness assessments including purple team testing. KEY RISK: A deficient SOC directly compromises the intermediary's ability to detect and respond to active cyber attacks on trading systems, exchange connectivity, and settlement infrastructure, potentially allowing threat actors extended dwell time to manipulate markets, exfiltrate client data, or disrupt capital market operations.
A12: CYB-2 | B12: Security Operations Centre | C12: SOC deployment and architecture | D12: 1. Obtain the SOC architecture documentation, including deployment model (in-house, MSSP, hybrid) and technology stack (SIEM, SOAR, EDR, NDR). 2. Review the SOC charter or terms of reference defining scope of monitoring, escalation authority, and integration with incident response. 3. Verify the SOC deployment model is appropriate for the entity's scale, with clear contractual obligations if MSSP is used (including SLAs for capital market-specific monitoring). 4. Confirm the SOC has documented runbooks for capital market-specific scenarios (trading system compromise, market data feed disruption, exchange connectivity anomalies, Bursa Malaysia link failure). | E12: SOC architecture document; SOC charter or terms of reference; MSSP contract with SLAs (if applicable); SOC runbook inventory covering capital market scenarios | F12: Inspection / Inquiry | M12: =IF(K12="Compliant",3,IF(K12="Partially Compliant",2,IF(K12="Non-Compliant",1,"")))
A13: CYB-2 | B13: Security Operations Centre | C13: SIEM log source coverage | D13: 1. Obtain the complete log source inventory feeding into the SIEM and compare against the entity's critical asset register. 2. Verify that all critical capital market systems are included: trading platforms (OMS/EMS), settlement systems, market data feed handlers, Bursa Malaysia connectivity gateways, client portals, algorithmic trading engines, and privileged access management systems. 3. Confirm log ingestion rates are within SIEM capacity and no critical log sources are being dropped or delayed. 4. Review the last log source coverage gap analysis and verify identified gaps have been remediated. 5. Inspect SIEM health dashboards to confirm all critical log sources show active and current data flow. | E13: SIEM log source inventory; critical asset register cross-reference; SIEM health/ingestion dashboard screenshots; log source coverage gap analysis report | F13: Inspection | M13: =IF(K13="Compliant",3,IF(K13="Partially Compliant",2,IF(K13="Non-Compliant",1,"")))
A14: CYB-2 | B14: Security Operations Centre | C14: Detection rules and use cases | D14: 1. Obtain the SIEM detection rule inventory and verify total rule count, categorisation, and last review date for each rule. 2. Select a sample of 15 detection rules (per sampling methodology for critical-tier controls) and assess whether they are tuned for capital market-specific attack patterns: unusual trading volumes or order patterns, market data manipulation attempts, unauthorised access to trading systems, privileged account abuse on settlement infrastructure, exchange connectivity anomalies. 3. Review the detection engineering process for creating, testing, and deploying new rules, including how false positive rates are managed. 4. Verify that detection rules are updated in response to new threat intelligence, recent incidents, and changes to the technology environment. 5. Confirm that detection rules cover MITRE ATT&CK techniques relevant to financial sector threat actors. | E14: SIEM detection rule inventory with review dates; sample detection rule configurations (15 rules per sampling methodology); detection engineering change log; false positive tuning records; MITRE ATT&CK coverage mapping | F14: Inspection / Inquiry | M14: =IF(K14="Compliant",3,IF(K14="Partially Compliant",2,IF(K14="Non-Compliant",1,"")))
A15: CYB-2 | B15: Security Operations Centre | C15: Trading hours and after-hours monitoring | D15: 1. Verify 24/7 monitoring coverage by reviewing SOC shift rosters for the last 3 months (per sampling methodology for operational records), confirming continuous staffing or MSSP coverage across all shifts. 2. Confirm that monitoring during Bursa Malaysia trading hours (pre-market, continuous trading, closing) has enhanced alerting thresholds and faster escalation SLAs. 3. Review after-hours monitoring procedures for batch settlement processing, overnight reconciliation runs, and market data feed maintenance windows. 4. Verify that weekend and public holiday monitoring covers scheduled maintenance, DR testing, and any overnight trading activity (e.g., global market exposure). 5. Interview SOC shift leads to confirm awareness of trading calendar, settlement deadlines, and market-critical time windows. | E15: SOC shift rosters (last 3 months per sampling methodology); trading hours escalation SLA documentation; after-hours monitoring procedures; Bursa Malaysia trading calendar integration evidence; weekend/holiday coverage records | F15: Inspection / Inquiry | M15: =IF(K15="Compliant",3,IF(K15="Partially Compliant",2,IF(K15="Non-Compliant",1,"")))
A16: CYB-2 | B16: Security Operations Centre | C16: Alert handling and triage | D16: 1. Select a sample of 8 security alerts from the last 3 months (per sampling methodology for critical-tier controls) and trace each from initial detection through triage, investigation, and disposition. 2. Verify each alert was triaged within the defined SLA and assigned an appropriate severity based on documented criteria. 3. Confirm that alert disposition is documented (true positive escalated, false positive with tuning action, benign true positive acknowledged). 4. Review alert escalation procedures and verify at least 3 escalated alerts reached the appropriate response team with documented handoff. 5. Determine whether trading system-related alerts receive priority handling compared to general IT alerts. | E16: Sample alert tickets with full lifecycle (8 alerts per sampling methodology); alert triage SLA compliance report; escalation records with handoff documentation (minimum 3); alert severity classification criteria | F16: Inspection | M16: =IF(K16="Compliant",3,IF(K16="Partially Compliant",2,IF(K16="Non-Compliant",1,"")))
A17: CYB-2 | B17: Security Operations Centre | C17: SOC performance metrics | D17: 1. Obtain SOC performance reports for the last 4 quarters and verify they track key metrics: mean time to detect (MTTD), mean time to respond (MTTR), alert volume trends, false positive rates, and escalation counts. 2. Verify MTTD and MTTR meet defined targets, particularly for critical-severity alerts affecting trading or settlement systems. 3. Review alert volume trends to identify whether volumes are increasing, stable, or decreasing and whether the SOC has adequate capacity. 4. Confirm metrics are reported to CISO and senior management with analysis of trends and recommended improvements. 5. Compare current quarter metrics against previous quarters to assess whether SOC performance is improving or degrading. | E17: Quarterly SOC performance reports (last 4 quarters); MTTD/MTTR trend data; alert volume analysis; SOC capacity assessment; management reporting on SOC metrics | F17: Inspection | M17: =IF(K17="Compliant",3,IF(K17="Partially Compliant",2,IF(K17="Non-Compliant",1,"")))
A18: CYB-2 | B18: Security Operations Centre | C18: SOC effectiveness assessment | D18: 1. Obtain the most recent SOC effectiveness assessment or maturity review (internal or external) conducted within the last 24 months. 2. Review the assessment scope and verify it covered people, process, and technology dimensions of SOC operations. 3. Inspect findings and recommendations, and verify an action plan was developed with assigned owners and target dates. 4. Confirm progress against the action plan by reviewing status updates and verify critical recommendations have been addressed. 5. Determine whether the assessment included testing of detection capability through purple team exercises or simulated attack scenarios targeting capital market systems. | E18: SOC effectiveness assessment report (most recent); remediation action plan with status tracking; purple team or detection testing results; SOC maturity scorecard | F18: Inspection | M18: =IF(K18="Compliant",3,IF(K18="Partially Compliant",2,IF(K18="Non-Compliant",1,"")))
A19: CYB-2 | B19: Security Operations Centre | C19: SOC staffing and skills | D19: 1. Review the SOC organisational structure, headcount, and verify staffing levels are adequate for 24/7 coverage without excessive overtime or single points of failure. 2. Obtain SOC analyst training records for the last 12 months and verify analysts have received training on capital market systems, trading protocols, and relevant regulatory requirements. 3. Confirm SOC analysts hold relevant certifications (e.g., GCIA, GCIH, OSCP, vendor-specific SIEM certifications) and the team has a skills development plan. 4. Interview SOC management on staff retention, succession planning, and how knowledge of capital market-specific threats and systems is maintained across the team. 5. Verify that onboarding procedures for new SOC analysts include orientation on capital market operations, critical system topology, and trading hour requirements. | E19: SOC organisational chart with headcount; analyst training records (last 12 months); certification inventory; skills development plan; staff retention and succession documentation; analyst onboarding checklist | F19: Inspection / Inquiry | M19: =IF(K19="Compliant",3,IF(K19="Partially Compliant",2,IF(K19="Non-Compliant",1,"")))
A20: CYB-3 — Vulnerability Management Programme
A21: PURPOSE: SC-GL/6-2023 requires capital market intermediaries to operate a comprehensive vulnerability management programme that systematically identifies, prioritises, and remediates vulnerabilities across all capital market systems. This ensures known weaknesses are addressed before they can be exploited by threat actors. EXPECTATION: The assessor should find a documented vulnerability management programme with defined scanning frequency and scope covering all capital market systems, risk-based patching SLAs that account for trading operational constraints, patch compliance tracking with management reporting, integration with penetration testing findings, a governed exception process, and quarterly trend reporting to the CISO and board. KEY RISK: Unpatched vulnerabilities in trading platforms, settlement systems, and exchange connectivity create exploitable attack vectors that could be leveraged for market disruption, data breach, or unauthorized access to client trading positions.
A22: CYB-3 | B22: Vulnerability Management Programme | C22: Vulnerability scanning programme | D22: 1. Obtain the vulnerability management policy or procedure and verify it defines scanning frequency, tools, responsibilities, and scope. 2. Review the scanning schedule and confirm scans are executed at the required frequency (e.g., weekly or monthly for critical systems, quarterly for others). 3. Verify that scanning tools are current, licensed, and configured with up-to-date vulnerability signatures. 4. Inspect the last 3 scan execution reports (per sampling methodology for operational records) to confirm scans completed successfully without premature termination or configuration errors. 5. Confirm that authenticated scanning is used for critical capital market systems to ensure accurate detection depth. | E22: Vulnerability management policy/procedure; scanning schedule; scanning tool licence and configuration records; scan execution reports (last 3 scans per sampling methodology); authenticated scan configuration evidence | F22: Inspection | M22: =IF(K22="Compliant",3,IF(K22="Partially Compliant",2,IF(K22="Non-Compliant",1,"")))
A23: CYB-3 | B23: Vulnerability Management Programme | C23: Asset coverage and scope | D23: 1. Obtain the vulnerability scanning asset scope and compare against the entity's complete IT asset register and critical system inventory. 2. Verify that all capital market systems are included in scanning scope: trading platforms, OMS/EMS, settlement systems, market data feed infrastructure, client portals, algorithmic trading engines, and supporting middleware. 3. Identify any systems excluded from scanning (e.g., legacy trading systems, vendor-managed platforms) and verify documented risk acceptance with compensating controls. 4. Confirm that cloud-hosted capital market workloads are included in the scanning programme. 5. Review asset discovery procedures to ensure new systems are added to scanning scope within a defined timeframe after deployment. | E23: Vulnerability scanning scope document; IT asset register cross-reference; excluded assets register with risk acceptance approvals; cloud workload scanning evidence; asset discovery procedure | F23: Inspection | M23: =IF(K23="Compliant",3,IF(K23="Partially Compliant",2,IF(K23="Non-Compliant",1,"")))
